2025-03-15 22:44:29,095 - app - [ERROR] - 10288 - 18444 - Exception on / [GET]
Traceback (most recent call last):
  File "C:\Users\Administrator\AppData\Roaming\Python\Python313\site-packages\flask\app.py", line 2190, in wsgi_app
    response = self.full_dispatch_request()
  File "C:\Users\Administrator\AppData\Roaming\Python\Python313\site-packages\flask\app.py", line 1487, in full_dispatch_request
    return self.finalize_request(rv)
           ~~~~~~~~~~~~~~~~~~~~~^^^^
  File "C:\Users\Administrator\AppData\Roaming\Python\Python313\site-packages\flask\app.py", line 1508, in finalize_request
    response = self.process_response(response)
  File "C:\Users\Administrator\AppData\Roaming\Python\Python313\site-packages\flask\app.py", line 2002, in process_response
    response = self.ensure_sync(func)(response)
  File "C:\Users\Administrator\Desktop\company_finance_tracker\app.py", line 64, in add_security_headers
    for key, values in csp.items()
                       ^^^^^^^^^
AttributeError: 'str' object has no attribute 'items'
2025-03-15 22:44:29,100 - app - [ERROR] - 10288 - 18444 - Request finalizing failed with an error while handling an error
Traceback (most recent call last):
  File "C:\Users\Administrator\AppData\Roaming\Python\Python313\site-packages\flask\app.py", line 2190, in wsgi_app
    response = self.full_dispatch_request()
  File "C:\Users\Administrator\AppData\Roaming\Python\Python313\site-packages\flask\app.py", line 1487, in full_dispatch_request
    return self.finalize_request(rv)
           ~~~~~~~~~~~~~~~~~~~~~^^^^
  File "C:\Users\Administrator\AppData\Roaming\Python\Python313\site-packages\flask\app.py", line 1508, in finalize_request
    response = self.process_response(response)
  File "C:\Users\Administrator\AppData\Roaming\Python\Python313\site-packages\flask\app.py", line 2002, in process_response
    response = self.ensure_sync(func)(response)
  File "C:\Users\Administrator\Desktop\company_finance_tracker\app.py", line 64, in add_security_headers
    for key, values in csp.items()
                       ^^^^^^^^^
AttributeError: 'str' object has no attribute 'items'

During handling of the above exception, another exception occurred:

Traceback (most recent call last):
  File "C:\Users\Administrator\AppData\Roaming\Python\Python313\site-packages\flask\app.py", line 1508, in finalize_request
    response = self.process_response(response)
  File "C:\Users\Administrator\AppData\Roaming\Python\Python313\site-packages\flask\app.py", line 2002, in process_response
    response = self.ensure_sync(func)(response)
  File "C:\Users\Administrator\Desktop\company_finance_tracker\app.py", line 64, in add_security_headers
    for key, values in csp.items()
                       ^^^^^^^^^
AttributeError: 'str' object has no attribute 'items'
2025-03-15 22:44:29,206 - app - [ERROR] - 10288 - 19416 - Exception on /favicon.ico [GET]
Traceback (most recent call last):
  File "C:\Users\Administrator\AppData\Roaming\Python\Python313\site-packages\flask\app.py", line 2190, in wsgi_app
    response = self.full_dispatch_request()
  File "C:\Users\Administrator\AppData\Roaming\Python\Python313\site-packages\flask\app.py", line 1487, in full_dispatch_request
    return self.finalize_request(rv)
           ~~~~~~~~~~~~~~~~~~~~~^^^^
  File "C:\Users\Administrator\AppData\Roaming\Python\Python313\site-packages\flask\app.py", line 1508, in finalize_request
    response = self.process_response(response)
  File "C:\Users\Administrator\AppData\Roaming\Python\Python313\site-packages\flask\app.py", line 2002, in process_response
    response = self.ensure_sync(func)(response)
  File "C:\Users\Administrator\Desktop\company_finance_tracker\app.py", line 64, in add_security_headers
    for key, values in csp.items()
                       ^^^^^^^^^
AttributeError: 'str' object has no attribute 'items'
2025-03-15 22:44:29,208 - app - [ERROR] - 10288 - 19416 - Request finalizing failed with an error while handling an error
Traceback (most recent call last):
  File "C:\Users\Administrator\AppData\Roaming\Python\Python313\site-packages\flask\app.py", line 2190, in wsgi_app
    response = self.full_dispatch_request()
  File "C:\Users\Administrator\AppData\Roaming\Python\Python313\site-packages\flask\app.py", line 1487, in full_dispatch_request
    return self.finalize_request(rv)
           ~~~~~~~~~~~~~~~~~~~~~^^^^
  File "C:\Users\Administrator\AppData\Roaming\Python\Python313\site-packages\flask\app.py", line 1508, in finalize_request
    response = self.process_response(response)
  File "C:\Users\Administrator\AppData\Roaming\Python\Python313\site-packages\flask\app.py", line 2002, in process_response
    response = self.ensure_sync(func)(response)
  File "C:\Users\Administrator\Desktop\company_finance_tracker\app.py", line 64, in add_security_headers
    for key, values in csp.items()
                       ^^^^^^^^^
AttributeError: 'str' object has no attribute 'items'

During handling of the above exception, another exception occurred:

Traceback (most recent call last):
  File "C:\Users\Administrator\AppData\Roaming\Python\Python313\site-packages\flask\app.py", line 1508, in finalize_request
    response = self.process_response(response)
  File "C:\Users\Administrator\AppData\Roaming\Python\Python313\site-packages\flask\app.py", line 2002, in process_response
    response = self.ensure_sync(func)(response)
  File "C:\Users\Administrator\Desktop\company_finance_tracker\app.py", line 64, in add_security_headers
    for key, values in csp.items()
                       ^^^^^^^^^
AttributeError: 'str' object has no attribute 'items'
2025-03-15 22:45:10,304 - app - [ERROR] - 10288 - 8288 - Exception on / [GET]
Traceback (most recent call last):
  File "C:\Users\Administrator\AppData\Roaming\Python\Python313\site-packages\flask\app.py", line 2190, in wsgi_app
    response = self.full_dispatch_request()
  File "C:\Users\Administrator\AppData\Roaming\Python\Python313\site-packages\flask\app.py", line 1487, in full_dispatch_request
    return self.finalize_request(rv)
           ~~~~~~~~~~~~~~~~~~~~~^^^^
  File "C:\Users\Administrator\AppData\Roaming\Python\Python313\site-packages\flask\app.py", line 1508, in finalize_request
    response = self.process_response(response)
  File "C:\Users\Administrator\AppData\Roaming\Python\Python313\site-packages\flask\app.py", line 2002, in process_response
    response = self.ensure_sync(func)(response)
  File "C:\Users\Administrator\Desktop\company_finance_tracker\app.py", line 64, in add_security_headers
    for key, values in csp.items()
                       ^^^^^^^^^
AttributeError: 'str' object has no attribute 'items'
2025-03-15 22:45:10,306 - app - [ERROR] - 10288 - 8288 - Request finalizing failed with an error while handling an error
Traceback (most recent call last):
  File "C:\Users\Administrator\AppData\Roaming\Python\Python313\site-packages\flask\app.py", line 2190, in wsgi_app
    response = self.full_dispatch_request()
  File "C:\Users\Administrator\AppData\Roaming\Python\Python313\site-packages\flask\app.py", line 1487, in full_dispatch_request
    return self.finalize_request(rv)
           ~~~~~~~~~~~~~~~~~~~~~^^^^
  File "C:\Users\Administrator\AppData\Roaming\Python\Python313\site-packages\flask\app.py", line 1508, in finalize_request
    response = self.process_response(response)
  File "C:\Users\Administrator\AppData\Roaming\Python\Python313\site-packages\flask\app.py", line 2002, in process_response
    response = self.ensure_sync(func)(response)
  File "C:\Users\Administrator\Desktop\company_finance_tracker\app.py", line 64, in add_security_headers
    for key, values in csp.items()
                       ^^^^^^^^^
AttributeError: 'str' object has no attribute 'items'

During handling of the above exception, another exception occurred:

Traceback (most recent call last):
  File "C:\Users\Administrator\AppData\Roaming\Python\Python313\site-packages\flask\app.py", line 1508, in finalize_request
    response = self.process_response(response)
  File "C:\Users\Administrator\AppData\Roaming\Python\Python313\site-packages\flask\app.py", line 2002, in process_response
    response = self.ensure_sync(func)(response)
  File "C:\Users\Administrator\Desktop\company_finance_tracker\app.py", line 64, in add_security_headers
    for key, values in csp.items()
                       ^^^^^^^^^
AttributeError: 'str' object has no attribute 'items'
2025-03-15 22:45:10,355 - app - [ERROR] - 10288 - 10700 - Exception on /favicon.ico [GET]
Traceback (most recent call last):
  File "C:\Users\Administrator\AppData\Roaming\Python\Python313\site-packages\flask\app.py", line 2190, in wsgi_app
    response = self.full_dispatch_request()
  File "C:\Users\Administrator\AppData\Roaming\Python\Python313\site-packages\flask\app.py", line 1487, in full_dispatch_request
    return self.finalize_request(rv)
           ~~~~~~~~~~~~~~~~~~~~~^^^^
  File "C:\Users\Administrator\AppData\Roaming\Python\Python313\site-packages\flask\app.py", line 1508, in finalize_request
    response = self.process_response(response)
  File "C:\Users\Administrator\AppData\Roaming\Python\Python313\site-packages\flask\app.py", line 2002, in process_response
    response = self.ensure_sync(func)(response)
  File "C:\Users\Administrator\Desktop\company_finance_tracker\app.py", line 64, in add_security_headers
    for key, values in csp.items()
                       ^^^^^^^^^
AttributeError: 'str' object has no attribute 'items'
2025-03-15 22:45:10,358 - app - [ERROR] - 10288 - 10700 - Request finalizing failed with an error while handling an error
Traceback (most recent call last):
  File "C:\Users\Administrator\AppData\Roaming\Python\Python313\site-packages\flask\app.py", line 2190, in wsgi_app
    response = self.full_dispatch_request()
  File "C:\Users\Administrator\AppData\Roaming\Python\Python313\site-packages\flask\app.py", line 1487, in full_dispatch_request
    return self.finalize_request(rv)
           ~~~~~~~~~~~~~~~~~~~~~^^^^
  File "C:\Users\Administrator\AppData\Roaming\Python\Python313\site-packages\flask\app.py", line 1508, in finalize_request
    response = self.process_response(response)
  File "C:\Users\Administrator\AppData\Roaming\Python\Python313\site-packages\flask\app.py", line 2002, in process_response
    response = self.ensure_sync(func)(response)
  File "C:\Users\Administrator\Desktop\company_finance_tracker\app.py", line 64, in add_security_headers
    for key, values in csp.items()
                       ^^^^^^^^^
AttributeError: 'str' object has no attribute 'items'

During handling of the above exception, another exception occurred:

Traceback (most recent call last):
  File "C:\Users\Administrator\AppData\Roaming\Python\Python313\site-packages\flask\app.py", line 1508, in finalize_request
    response = self.process_response(response)
  File "C:\Users\Administrator\AppData\Roaming\Python\Python313\site-packages\flask\app.py", line 2002, in process_response
    response = self.ensure_sync(func)(response)
  File "C:\Users\Administrator\Desktop\company_finance_tracker\app.py", line 64, in add_security_headers
    for key, values in csp.items()
                       ^^^^^^^^^
AttributeError: 'str' object has no attribute 'items'
2025-03-15 22:45:11,428 - app - [ERROR] - 10288 - 18444 - Exception on / [GET]
Traceback (most recent call last):
  File "C:\Users\Administrator\AppData\Roaming\Python\Python313\site-packages\flask\app.py", line 2190, in wsgi_app
    response = self.full_dispatch_request()
  File "C:\Users\Administrator\AppData\Roaming\Python\Python313\site-packages\flask\app.py", line 1487, in full_dispatch_request
    return self.finalize_request(rv)
           ~~~~~~~~~~~~~~~~~~~~~^^^^
  File "C:\Users\Administrator\AppData\Roaming\Python\Python313\site-packages\flask\app.py", line 1508, in finalize_request
    response = self.process_response(response)
  File "C:\Users\Administrator\AppData\Roaming\Python\Python313\site-packages\flask\app.py", line 2002, in process_response
    response = self.ensure_sync(func)(response)
  File "C:\Users\Administrator\Desktop\company_finance_tracker\app.py", line 64, in add_security_headers
    for key, values in csp.items()
                       ^^^^^^^^^
AttributeError: 'str' object has no attribute 'items'
2025-03-15 22:45:11,430 - app - [ERROR] - 10288 - 18444 - Request finalizing failed with an error while handling an error
Traceback (most recent call last):
  File "C:\Users\Administrator\AppData\Roaming\Python\Python313\site-packages\flask\app.py", line 2190, in wsgi_app
    response = self.full_dispatch_request()
  File "C:\Users\Administrator\AppData\Roaming\Python\Python313\site-packages\flask\app.py", line 1487, in full_dispatch_request
    return self.finalize_request(rv)
           ~~~~~~~~~~~~~~~~~~~~~^^^^
  File "C:\Users\Administrator\AppData\Roaming\Python\Python313\site-packages\flask\app.py", line 1508, in finalize_request
    response = self.process_response(response)
  File "C:\Users\Administrator\AppData\Roaming\Python\Python313\site-packages\flask\app.py", line 2002, in process_response
    response = self.ensure_sync(func)(response)
  File "C:\Users\Administrator\Desktop\company_finance_tracker\app.py", line 64, in add_security_headers
    for key, values in csp.items()
                       ^^^^^^^^^
AttributeError: 'str' object has no attribute 'items'

During handling of the above exception, another exception occurred:

Traceback (most recent call last):
  File "C:\Users\Administrator\AppData\Roaming\Python\Python313\site-packages\flask\app.py", line 1508, in finalize_request
    response = self.process_response(response)
  File "C:\Users\Administrator\AppData\Roaming\Python\Python313\site-packages\flask\app.py", line 2002, in process_response
    response = self.ensure_sync(func)(response)
  File "C:\Users\Administrator\Desktop\company_finance_tracker\app.py", line 64, in add_security_headers
    for key, values in csp.items()
                       ^^^^^^^^^
AttributeError: 'str' object has no attribute 'items'
2025-03-15 22:45:11,484 - app - [ERROR] - 10288 - 19416 - Exception on /favicon.ico [GET]
Traceback (most recent call last):
  File "C:\Users\Administrator\AppData\Roaming\Python\Python313\site-packages\flask\app.py", line 2190, in wsgi_app
    response = self.full_dispatch_request()
  File "C:\Users\Administrator\AppData\Roaming\Python\Python313\site-packages\flask\app.py", line 1487, in full_dispatch_request
    return self.finalize_request(rv)
           ~~~~~~~~~~~~~~~~~~~~~^^^^
  File "C:\Users\Administrator\AppData\Roaming\Python\Python313\site-packages\flask\app.py", line 1508, in finalize_request
    response = self.process_response(response)
  File "C:\Users\Administrator\AppData\Roaming\Python\Python313\site-packages\flask\app.py", line 2002, in process_response
    response = self.ensure_sync(func)(response)
  File "C:\Users\Administrator\Desktop\company_finance_tracker\app.py", line 64, in add_security_headers
    for key, values in csp.items()
                       ^^^^^^^^^
AttributeError: 'str' object has no attribute 'items'
2025-03-15 22:45:11,486 - app - [ERROR] - 10288 - 19416 - Request finalizing failed with an error while handling an error
Traceback (most recent call last):
  File "C:\Users\Administrator\AppData\Roaming\Python\Python313\site-packages\flask\app.py", line 2190, in wsgi_app
    response = self.full_dispatch_request()
  File "C:\Users\Administrator\AppData\Roaming\Python\Python313\site-packages\flask\app.py", line 1487, in full_dispatch_request
    return self.finalize_request(rv)
           ~~~~~~~~~~~~~~~~~~~~~^^^^
  File "C:\Users\Administrator\AppData\Roaming\Python\Python313\site-packages\flask\app.py", line 1508, in finalize_request
    response = self.process_response(response)
  File "C:\Users\Administrator\AppData\Roaming\Python\Python313\site-packages\flask\app.py", line 2002, in process_response
    response = self.ensure_sync(func)(response)
  File "C:\Users\Administrator\Desktop\company_finance_tracker\app.py", line 64, in add_security_headers
    for key, values in csp.items()
                       ^^^^^^^^^
AttributeError: 'str' object has no attribute 'items'

During handling of the above exception, another exception occurred:

Traceback (most recent call last):
  File "C:\Users\Administrator\AppData\Roaming\Python\Python313\site-packages\flask\app.py", line 1508, in finalize_request
    response = self.process_response(response)
  File "C:\Users\Administrator\AppData\Roaming\Python\Python313\site-packages\flask\app.py", line 2002, in process_response
    response = self.ensure_sync(func)(response)
  File "C:\Users\Administrator\Desktop\company_finance_tracker\app.py", line 64, in add_security_headers
    for key, values in csp.items()
                       ^^^^^^^^^
AttributeError: 'str' object has no attribute 'items'
2025-03-15 22:46:18,457 - app - [ERROR] - 10288 - 8288 - Exception on / [GET]
Traceback (most recent call last):
  File "C:\Users\Administrator\AppData\Roaming\Python\Python313\site-packages\flask\app.py", line 2190, in wsgi_app
    response = self.full_dispatch_request()
  File "C:\Users\Administrator\AppData\Roaming\Python\Python313\site-packages\flask\app.py", line 1487, in full_dispatch_request
    return self.finalize_request(rv)
           ~~~~~~~~~~~~~~~~~~~~~^^^^
  File "C:\Users\Administrator\AppData\Roaming\Python\Python313\site-packages\flask\app.py", line 1508, in finalize_request
    response = self.process_response(response)
  File "C:\Users\Administrator\AppData\Roaming\Python\Python313\site-packages\flask\app.py", line 2002, in process_response
    response = self.ensure_sync(func)(response)
  File "C:\Users\Administrator\Desktop\company_finance_tracker\app.py", line 64, in add_security_headers
    for key, values in csp.items()
                       ^^^^^^^^^
AttributeError: 'str' object has no attribute 'items'
2025-03-15 22:46:18,462 - app - [ERROR] - 10288 - 8288 - Request finalizing failed with an error while handling an error
Traceback (most recent call last):
  File "C:\Users\Administrator\AppData\Roaming\Python\Python313\site-packages\flask\app.py", line 2190, in wsgi_app
    response = self.full_dispatch_request()
  File "C:\Users\Administrator\AppData\Roaming\Python\Python313\site-packages\flask\app.py", line 1487, in full_dispatch_request
    return self.finalize_request(rv)
           ~~~~~~~~~~~~~~~~~~~~~^^^^
  File "C:\Users\Administrator\AppData\Roaming\Python\Python313\site-packages\flask\app.py", line 1508, in finalize_request
    response = self.process_response(response)
  File "C:\Users\Administrator\AppData\Roaming\Python\Python313\site-packages\flask\app.py", line 2002, in process_response
    response = self.ensure_sync(func)(response)
  File "C:\Users\Administrator\Desktop\company_finance_tracker\app.py", line 64, in add_security_headers
    for key, values in csp.items()
                       ^^^^^^^^^
AttributeError: 'str' object has no attribute 'items'

During handling of the above exception, another exception occurred:

Traceback (most recent call last):
  File "C:\Users\Administrator\AppData\Roaming\Python\Python313\site-packages\flask\app.py", line 1508, in finalize_request
    response = self.process_response(response)
  File "C:\Users\Administrator\AppData\Roaming\Python\Python313\site-packages\flask\app.py", line 2002, in process_response
    response = self.ensure_sync(func)(response)
  File "C:\Users\Administrator\Desktop\company_finance_tracker\app.py", line 64, in add_security_headers
    for key, values in csp.items()
                       ^^^^^^^^^
AttributeError: 'str' object has no attribute 'items'
2025-03-15 22:46:18,690 - app - [ERROR] - 10288 - 10700 - Exception on /favicon.ico [GET]
Traceback (most recent call last):
  File "C:\Users\Administrator\AppData\Roaming\Python\Python313\site-packages\flask\app.py", line 2190, in wsgi_app
    response = self.full_dispatch_request()
  File "C:\Users\Administrator\AppData\Roaming\Python\Python313\site-packages\flask\app.py", line 1487, in full_dispatch_request
    return self.finalize_request(rv)
           ~~~~~~~~~~~~~~~~~~~~~^^^^
  File "C:\Users\Administrator\AppData\Roaming\Python\Python313\site-packages\flask\app.py", line 1508, in finalize_request
    response = self.process_response(response)
  File "C:\Users\Administrator\AppData\Roaming\Python\Python313\site-packages\flask\app.py", line 2002, in process_response
    response = self.ensure_sync(func)(response)
  File "C:\Users\Administrator\Desktop\company_finance_tracker\app.py", line 64, in add_security_headers
    for key, values in csp.items()
                       ^^^^^^^^^
AttributeError: 'str' object has no attribute 'items'
2025-03-15 22:46:18,695 - app - [ERROR] - 10288 - 10700 - Request finalizing failed with an error while handling an error
Traceback (most recent call last):
  File "C:\Users\Administrator\AppData\Roaming\Python\Python313\site-packages\flask\app.py", line 2190, in wsgi_app
    response = self.full_dispatch_request()
  File "C:\Users\Administrator\AppData\Roaming\Python\Python313\site-packages\flask\app.py", line 1487, in full_dispatch_request
    return self.finalize_request(rv)
           ~~~~~~~~~~~~~~~~~~~~~^^^^
  File "C:\Users\Administrator\AppData\Roaming\Python\Python313\site-packages\flask\app.py", line 1508, in finalize_request
    response = self.process_response(response)
  File "C:\Users\Administrator\AppData\Roaming\Python\Python313\site-packages\flask\app.py", line 2002, in process_response
    response = self.ensure_sync(func)(response)
  File "C:\Users\Administrator\Desktop\company_finance_tracker\app.py", line 64, in add_security_headers
    for key, values in csp.items()
                       ^^^^^^^^^
AttributeError: 'str' object has no attribute 'items'

During handling of the above exception, another exception occurred:

Traceback (most recent call last):
  File "C:\Users\Administrator\AppData\Roaming\Python\Python313\site-packages\flask\app.py", line 1508, in finalize_request
    response = self.process_response(response)
  File "C:\Users\Administrator\AppData\Roaming\Python\Python313\site-packages\flask\app.py", line 2002, in process_response
    response = self.ensure_sync(func)(response)
  File "C:\Users\Administrator\Desktop\company_finance_tracker\app.py", line 64, in add_security_headers
    for key, values in csp.items()
                       ^^^^^^^^^
AttributeError: 'str' object has no attribute 'items'
2025-03-15 22:51:46,607 - app - [ERROR] - 10288 - 18444 - Exception on / [GET]
Traceback (most recent call last):
  File "C:\Users\Administrator\AppData\Roaming\Python\Python313\site-packages\flask\app.py", line 2190, in wsgi_app
  File "C:\Users\Administrator\AppData\Roaming\Python\Python313\site-packages\flask\app.py", line 1487, in full_dispatch_request
  File "C:\Users\Administrator\AppData\Roaming\Python\Python313\site-packages\flask\app.py", line 1508, in finalize_request
  File "C:\Users\Administrator\AppData\Roaming\Python\Python313\site-packages\flask\app.py", line 2002, in process_response
  File "C:\Users\Administrator\Desktop\company_finance_tracker\app.py", line 64, in add_security_headers
    for key, values in csp.items()
                       ^^^^^^^^^
AttributeError: 'str' object has no attribute 'items'
2025-03-15 22:51:46,612 - app - [ERROR] - 10288 - 18444 - Request finalizing failed with an error while handling an error
Traceback (most recent call last):
  File "C:\Users\Administrator\AppData\Roaming\Python\Python313\site-packages\flask\app.py", line 2190, in wsgi_app
  File "C:\Users\Administrator\AppData\Roaming\Python\Python313\site-packages\flask\app.py", line 1487, in full_dispatch_request
  File "C:\Users\Administrator\AppData\Roaming\Python\Python313\site-packages\flask\app.py", line 1508, in finalize_request
  File "C:\Users\Administrator\AppData\Roaming\Python\Python313\site-packages\flask\app.py", line 2002, in process_response
  File "C:\Users\Administrator\Desktop\company_finance_tracker\app.py", line 64, in add_security_headers
    for key, values in csp.items()
                       ^^^^^^^^^
AttributeError: 'str' object has no attribute 'items'

During handling of the above exception, another exception occurred:

Traceback (most recent call last):
  File "C:\Users\Administrator\AppData\Roaming\Python\Python313\site-packages\flask\app.py", line 1508, in finalize_request
  File "C:\Users\Administrator\AppData\Roaming\Python\Python313\site-packages\flask\app.py", line 2002, in process_response
  File "C:\Users\Administrator\Desktop\company_finance_tracker\app.py", line 64, in add_security_headers
    for key, values in csp.items()
                       ^^^^^^^^^
AttributeError: 'str' object has no attribute 'items'
2025-03-15 22:51:46,661 - app - [ERROR] - 10288 - 19416 - Exception on /favicon.ico [GET]
Traceback (most recent call last):
  File "C:\Users\Administrator\AppData\Roaming\Python\Python313\site-packages\flask\app.py", line 2190, in wsgi_app
  File "C:\Users\Administrator\AppData\Roaming\Python\Python313\site-packages\flask\app.py", line 1487, in full_dispatch_request
  File "C:\Users\Administrator\AppData\Roaming\Python\Python313\site-packages\flask\app.py", line 1508, in finalize_request
  File "C:\Users\Administrator\AppData\Roaming\Python\Python313\site-packages\flask\app.py", line 2002, in process_response
  File "C:\Users\Administrator\Desktop\company_finance_tracker\app.py", line 64, in add_security_headers
    for key, values in csp.items()
                       ^^^^^^^^^
AttributeError: 'str' object has no attribute 'items'
2025-03-15 22:51:46,663 - app - [ERROR] - 10288 - 19416 - Request finalizing failed with an error while handling an error
Traceback (most recent call last):
  File "C:\Users\Administrator\AppData\Roaming\Python\Python313\site-packages\flask\app.py", line 2190, in wsgi_app
  File "C:\Users\Administrator\AppData\Roaming\Python\Python313\site-packages\flask\app.py", line 1487, in full_dispatch_request
  File "C:\Users\Administrator\AppData\Roaming\Python\Python313\site-packages\flask\app.py", line 1508, in finalize_request
  File "C:\Users\Administrator\AppData\Roaming\Python\Python313\site-packages\flask\app.py", line 2002, in process_response
  File "C:\Users\Administrator\Desktop\company_finance_tracker\app.py", line 64, in add_security_headers
    for key, values in csp.items()
                       ^^^^^^^^^
AttributeError: 'str' object has no attribute 'items'

During handling of the above exception, another exception occurred:

Traceback (most recent call last):
  File "C:\Users\Administrator\AppData\Roaming\Python\Python313\site-packages\flask\app.py", line 1508, in finalize_request
  File "C:\Users\Administrator\AppData\Roaming\Python\Python313\site-packages\flask\app.py", line 2002, in process_response
  File "C:\Users\Administrator\Desktop\company_finance_tracker\app.py", line 64, in add_security_headers
    for key, values in csp.items()
                       ^^^^^^^^^
AttributeError: 'str' object has no attribute 'items'
2025-03-15 22:51:47,629 - app - [ERROR] - 10288 - 8288 - Exception on / [GET]
Traceback (most recent call last):
  File "C:\Users\Administrator\AppData\Roaming\Python\Python313\site-packages\flask\app.py", line 2190, in wsgi_app
  File "C:\Users\Administrator\AppData\Roaming\Python\Python313\site-packages\flask\app.py", line 1487, in full_dispatch_request
  File "C:\Users\Administrator\AppData\Roaming\Python\Python313\site-packages\flask\app.py", line 1508, in finalize_request
  File "C:\Users\Administrator\AppData\Roaming\Python\Python313\site-packages\flask\app.py", line 2002, in process_response
  File "C:\Users\Administrator\Desktop\company_finance_tracker\app.py", line 64, in add_security_headers
    for key, values in csp.items()
                       ^^^^^^^^^
AttributeError: 'str' object has no attribute 'items'
2025-03-15 22:51:47,632 - app - [ERROR] - 10288 - 8288 - Request finalizing failed with an error while handling an error
Traceback (most recent call last):
  File "C:\Users\Administrator\AppData\Roaming\Python\Python313\site-packages\flask\app.py", line 2190, in wsgi_app
  File "C:\Users\Administrator\AppData\Roaming\Python\Python313\site-packages\flask\app.py", line 1487, in full_dispatch_request
  File "C:\Users\Administrator\AppData\Roaming\Python\Python313\site-packages\flask\app.py", line 1508, in finalize_request
  File "C:\Users\Administrator\AppData\Roaming\Python\Python313\site-packages\flask\app.py", line 2002, in process_response
  File "C:\Users\Administrator\Desktop\company_finance_tracker\app.py", line 64, in add_security_headers
    for key, values in csp.items()
                       ^^^^^^^^^
AttributeError: 'str' object has no attribute 'items'

During handling of the above exception, another exception occurred:

Traceback (most recent call last):
  File "C:\Users\Administrator\AppData\Roaming\Python\Python313\site-packages\flask\app.py", line 1508, in finalize_request
  File "C:\Users\Administrator\AppData\Roaming\Python\Python313\site-packages\flask\app.py", line 2002, in process_response
  File "C:\Users\Administrator\Desktop\company_finance_tracker\app.py", line 64, in add_security_headers
    for key, values in csp.items()
                       ^^^^^^^^^
AttributeError: 'str' object has no attribute 'items'
2025-03-15 22:51:47,691 - app - [ERROR] - 10288 - 10700 - Exception on /favicon.ico [GET]
Traceback (most recent call last):
  File "C:\Users\Administrator\AppData\Roaming\Python\Python313\site-packages\flask\app.py", line 2190, in wsgi_app
  File "C:\Users\Administrator\AppData\Roaming\Python\Python313\site-packages\flask\app.py", line 1487, in full_dispatch_request
  File "C:\Users\Administrator\AppData\Roaming\Python\Python313\site-packages\flask\app.py", line 1508, in finalize_request
  File "C:\Users\Administrator\AppData\Roaming\Python\Python313\site-packages\flask\app.py", line 2002, in process_response
  File "C:\Users\Administrator\Desktop\company_finance_tracker\app.py", line 64, in add_security_headers
    for key, values in csp.items()
                       ^^^^^^^^^
AttributeError: 'str' object has no attribute 'items'
2025-03-15 22:51:47,693 - app - [ERROR] - 10288 - 10700 - Request finalizing failed with an error while handling an error
Traceback (most recent call last):
  File "C:\Users\Administrator\AppData\Roaming\Python\Python313\site-packages\flask\app.py", line 2190, in wsgi_app
  File "C:\Users\Administrator\AppData\Roaming\Python\Python313\site-packages\flask\app.py", line 1487, in full_dispatch_request
  File "C:\Users\Administrator\AppData\Roaming\Python\Python313\site-packages\flask\app.py", line 1508, in finalize_request
  File "C:\Users\Administrator\AppData\Roaming\Python\Python313\site-packages\flask\app.py", line 2002, in process_response
  File "C:\Users\Administrator\Desktop\company_finance_tracker\app.py", line 64, in add_security_headers
    for key, values in csp.items()
                       ^^^^^^^^^
AttributeError: 'str' object has no attribute 'items'

During handling of the above exception, another exception occurred:

Traceback (most recent call last):
  File "C:\Users\Administrator\AppData\Roaming\Python\Python313\site-packages\flask\app.py", line 1508, in finalize_request
  File "C:\Users\Administrator\AppData\Roaming\Python\Python313\site-packages\flask\app.py", line 2002, in process_response
  File "C:\Users\Administrator\Desktop\company_finance_tracker\app.py", line 64, in add_security_headers
    for key, values in csp.items()
                       ^^^^^^^^^
AttributeError: 'str' object has no attribute 'items'
2025-03-15 22:51:48,557 - app - [ERROR] - 10288 - 18444 - Exception on / [GET]
Traceback (most recent call last):
  File "C:\Users\Administrator\AppData\Roaming\Python\Python313\site-packages\flask\app.py", line 2190, in wsgi_app
  File "C:\Users\Administrator\AppData\Roaming\Python\Python313\site-packages\flask\app.py", line 1487, in full_dispatch_request
  File "C:\Users\Administrator\AppData\Roaming\Python\Python313\site-packages\flask\app.py", line 1508, in finalize_request
  File "C:\Users\Administrator\AppData\Roaming\Python\Python313\site-packages\flask\app.py", line 2002, in process_response
  File "C:\Users\Administrator\Desktop\company_finance_tracker\app.py", line 64, in add_security_headers
    for key, values in csp.items()
                       ^^^^^^^^^
AttributeError: 'str' object has no attribute 'items'
2025-03-15 22:51:48,560 - app - [ERROR] - 10288 - 18444 - Request finalizing failed with an error while handling an error
Traceback (most recent call last):
  File "C:\Users\Administrator\AppData\Roaming\Python\Python313\site-packages\flask\app.py", line 2190, in wsgi_app
  File "C:\Users\Administrator\AppData\Roaming\Python\Python313\site-packages\flask\app.py", line 1487, in full_dispatch_request
  File "C:\Users\Administrator\AppData\Roaming\Python\Python313\site-packages\flask\app.py", line 1508, in finalize_request
  File "C:\Users\Administrator\AppData\Roaming\Python\Python313\site-packages\flask\app.py", line 2002, in process_response
  File "C:\Users\Administrator\Desktop\company_finance_tracker\app.py", line 64, in add_security_headers
    for key, values in csp.items()
                       ^^^^^^^^^
AttributeError: 'str' object has no attribute 'items'

During handling of the above exception, another exception occurred:

Traceback (most recent call last):
  File "C:\Users\Administrator\AppData\Roaming\Python\Python313\site-packages\flask\app.py", line 1508, in finalize_request
  File "C:\Users\Administrator\AppData\Roaming\Python\Python313\site-packages\flask\app.py", line 2002, in process_response
  File "C:\Users\Administrator\Desktop\company_finance_tracker\app.py", line 64, in add_security_headers
    for key, values in csp.items()
                       ^^^^^^^^^
AttributeError: 'str' object has no attribute 'items'
2025-03-15 22:51:48,610 - app - [ERROR] - 10288 - 19416 - Exception on /favicon.ico [GET]
Traceback (most recent call last):
  File "C:\Users\Administrator\AppData\Roaming\Python\Python313\site-packages\flask\app.py", line 2190, in wsgi_app
  File "C:\Users\Administrator\AppData\Roaming\Python\Python313\site-packages\flask\app.py", line 1487, in full_dispatch_request
  File "C:\Users\Administrator\AppData\Roaming\Python\Python313\site-packages\flask\app.py", line 1508, in finalize_request
  File "C:\Users\Administrator\AppData\Roaming\Python\Python313\site-packages\flask\app.py", line 2002, in process_response
  File "C:\Users\Administrator\Desktop\company_finance_tracker\app.py", line 64, in add_security_headers
    for key, values in csp.items()
                       ^^^^^^^^^
AttributeError: 'str' object has no attribute 'items'
2025-03-15 22:51:48,613 - app - [ERROR] - 10288 - 19416 - Request finalizing failed with an error while handling an error
Traceback (most recent call last):
  File "C:\Users\Administrator\AppData\Roaming\Python\Python313\site-packages\flask\app.py", line 2190, in wsgi_app
  File "C:\Users\Administrator\AppData\Roaming\Python\Python313\site-packages\flask\app.py", line 1487, in full_dispatch_request
  File "C:\Users\Administrator\AppData\Roaming\Python\Python313\site-packages\flask\app.py", line 1508, in finalize_request
  File "C:\Users\Administrator\AppData\Roaming\Python\Python313\site-packages\flask\app.py", line 2002, in process_response
  File "C:\Users\Administrator\Desktop\company_finance_tracker\app.py", line 64, in add_security_headers
    for key, values in csp.items()
                       ^^^^^^^^^
AttributeError: 'str' object has no attribute 'items'

During handling of the above exception, another exception occurred:

Traceback (most recent call last):
  File "C:\Users\Administrator\AppData\Roaming\Python\Python313\site-packages\flask\app.py", line 1508, in finalize_request
  File "C:\Users\Administrator\AppData\Roaming\Python\Python313\site-packages\flask\app.py", line 2002, in process_response
  File "C:\Users\Administrator\Desktop\company_finance_tracker\app.py", line 64, in add_security_headers
    for key, values in csp.items()
                       ^^^^^^^^^
AttributeError: 'str' object has no attribute 'items'
2025-03-15 22:51:48,773 - app - [ERROR] - 10288 - 8288 - Exception on / [GET]
Traceback (most recent call last):
  File "C:\Users\Administrator\AppData\Roaming\Python\Python313\site-packages\flask\app.py", line 2190, in wsgi_app
  File "C:\Users\Administrator\AppData\Roaming\Python\Python313\site-packages\flask\app.py", line 1487, in full_dispatch_request
  File "C:\Users\Administrator\AppData\Roaming\Python\Python313\site-packages\flask\app.py", line 1508, in finalize_request
  File "C:\Users\Administrator\AppData\Roaming\Python\Python313\site-packages\flask\app.py", line 2002, in process_response
  File "C:\Users\Administrator\Desktop\company_finance_tracker\app.py", line 64, in add_security_headers
    for key, values in csp.items()
                       ^^^^^^^^^
AttributeError: 'str' object has no attribute 'items'
2025-03-15 22:51:48,776 - app - [ERROR] - 10288 - 8288 - Request finalizing failed with an error while handling an error
Traceback (most recent call last):
  File "C:\Users\Administrator\AppData\Roaming\Python\Python313\site-packages\flask\app.py", line 2190, in wsgi_app
  File "C:\Users\Administrator\AppData\Roaming\Python\Python313\site-packages\flask\app.py", line 1487, in full_dispatch_request
  File "C:\Users\Administrator\AppData\Roaming\Python\Python313\site-packages\flask\app.py", line 1508, in finalize_request
  File "C:\Users\Administrator\AppData\Roaming\Python\Python313\site-packages\flask\app.py", line 2002, in process_response
  File "C:\Users\Administrator\Desktop\company_finance_tracker\app.py", line 64, in add_security_headers
    for key, values in csp.items()
                       ^^^^^^^^^
AttributeError: 'str' object has no attribute 'items'

During handling of the above exception, another exception occurred:

Traceback (most recent call last):
  File "C:\Users\Administrator\AppData\Roaming\Python\Python313\site-packages\flask\app.py", line 1508, in finalize_request
  File "C:\Users\Administrator\AppData\Roaming\Python\Python313\site-packages\flask\app.py", line 2002, in process_response
  File "C:\Users\Administrator\Desktop\company_finance_tracker\app.py", line 64, in add_security_headers
    for key, values in csp.items()
                       ^^^^^^^^^
AttributeError: 'str' object has no attribute 'items'
2025-03-15 22:51:48,831 - app - [ERROR] - 10288 - 10700 - Exception on /favicon.ico [GET]
Traceback (most recent call last):
  File "C:\Users\Administrator\AppData\Roaming\Python\Python313\site-packages\flask\app.py", line 2190, in wsgi_app
  File "C:\Users\Administrator\AppData\Roaming\Python\Python313\site-packages\flask\app.py", line 1487, in full_dispatch_request
  File "C:\Users\Administrator\AppData\Roaming\Python\Python313\site-packages\flask\app.py", line 1508, in finalize_request
  File "C:\Users\Administrator\AppData\Roaming\Python\Python313\site-packages\flask\app.py", line 2002, in process_response
  File "C:\Users\Administrator\Desktop\company_finance_tracker\app.py", line 64, in add_security_headers
    for key, values in csp.items()
                       ^^^^^^^^^
AttributeError: 'str' object has no attribute 'items'
2025-03-15 22:51:48,832 - app - [ERROR] - 10288 - 10700 - Request finalizing failed with an error while handling an error
Traceback (most recent call last):
  File "C:\Users\Administrator\AppData\Roaming\Python\Python313\site-packages\flask\app.py", line 2190, in wsgi_app
  File "C:\Users\Administrator\AppData\Roaming\Python\Python313\site-packages\flask\app.py", line 1487, in full_dispatch_request
  File "C:\Users\Administrator\AppData\Roaming\Python\Python313\site-packages\flask\app.py", line 1508, in finalize_request
  File "C:\Users\Administrator\AppData\Roaming\Python\Python313\site-packages\flask\app.py", line 2002, in process_response
  File "C:\Users\Administrator\Desktop\company_finance_tracker\app.py", line 64, in add_security_headers
    for key, values in csp.items()
                       ^^^^^^^^^
AttributeError: 'str' object has no attribute 'items'

During handling of the above exception, another exception occurred:

Traceback (most recent call last):
  File "C:\Users\Administrator\AppData\Roaming\Python\Python313\site-packages\flask\app.py", line 1508, in finalize_request
  File "C:\Users\Administrator\AppData\Roaming\Python\Python313\site-packages\flask\app.py", line 2002, in process_response
  File "C:\Users\Administrator\Desktop\company_finance_tracker\app.py", line 64, in add_security_headers
    for key, values in csp.items()
                       ^^^^^^^^^
AttributeError: 'str' object has no attribute 'items'
2025-03-15 22:51:49,046 - app - [ERROR] - 10288 - 18444 - Exception on / [GET]
Traceback (most recent call last):
  File "C:\Users\Administrator\AppData\Roaming\Python\Python313\site-packages\flask\app.py", line 2190, in wsgi_app
  File "C:\Users\Administrator\AppData\Roaming\Python\Python313\site-packages\flask\app.py", line 1487, in full_dispatch_request
  File "C:\Users\Administrator\AppData\Roaming\Python\Python313\site-packages\flask\app.py", line 1508, in finalize_request
  File "C:\Users\Administrator\AppData\Roaming\Python\Python313\site-packages\flask\app.py", line 2002, in process_response
  File "C:\Users\Administrator\Desktop\company_finance_tracker\app.py", line 64, in add_security_headers
    for key, values in csp.items()
                       ^^^^^^^^^
AttributeError: 'str' object has no attribute 'items'
2025-03-15 22:51:49,047 - app - [ERROR] - 10288 - 18444 - Request finalizing failed with an error while handling an error
Traceback (most recent call last):
  File "C:\Users\Administrator\AppData\Roaming\Python\Python313\site-packages\flask\app.py", line 2190, in wsgi_app
  File "C:\Users\Administrator\AppData\Roaming\Python\Python313\site-packages\flask\app.py", line 1487, in full_dispatch_request
  File "C:\Users\Administrator\AppData\Roaming\Python\Python313\site-packages\flask\app.py", line 1508, in finalize_request
  File "C:\Users\Administrator\AppData\Roaming\Python\Python313\site-packages\flask\app.py", line 2002, in process_response
  File "C:\Users\Administrator\Desktop\company_finance_tracker\app.py", line 64, in add_security_headers
    for key, values in csp.items()
                       ^^^^^^^^^
AttributeError: 'str' object has no attribute 'items'

During handling of the above exception, another exception occurred:

Traceback (most recent call last):
  File "C:\Users\Administrator\AppData\Roaming\Python\Python313\site-packages\flask\app.py", line 1508, in finalize_request
  File "C:\Users\Administrator\AppData\Roaming\Python\Python313\site-packages\flask\app.py", line 2002, in process_response
  File "C:\Users\Administrator\Desktop\company_finance_tracker\app.py", line 64, in add_security_headers
    for key, values in csp.items()
                       ^^^^^^^^^
AttributeError: 'str' object has no attribute 'items'
2025-03-15 22:51:49,105 - app - [ERROR] - 10288 - 19416 - Exception on /favicon.ico [GET]
Traceback (most recent call last):
  File "C:\Users\Administrator\AppData\Roaming\Python\Python313\site-packages\flask\app.py", line 2190, in wsgi_app
  File "C:\Users\Administrator\AppData\Roaming\Python\Python313\site-packages\flask\app.py", line 1487, in full_dispatch_request
  File "C:\Users\Administrator\AppData\Roaming\Python\Python313\site-packages\flask\app.py", line 1508, in finalize_request
  File "C:\Users\Administrator\AppData\Roaming\Python\Python313\site-packages\flask\app.py", line 2002, in process_response
  File "C:\Users\Administrator\Desktop\company_finance_tracker\app.py", line 64, in add_security_headers
    for key, values in csp.items()
                       ^^^^^^^^^
AttributeError: 'str' object has no attribute 'items'
2025-03-15 22:51:49,108 - app - [ERROR] - 10288 - 19416 - Request finalizing failed with an error while handling an error
Traceback (most recent call last):
  File "C:\Users\Administrator\AppData\Roaming\Python\Python313\site-packages\flask\app.py", line 2190, in wsgi_app
  File "C:\Users\Administrator\AppData\Roaming\Python\Python313\site-packages\flask\app.py", line 1487, in full_dispatch_request
  File "C:\Users\Administrator\AppData\Roaming\Python\Python313\site-packages\flask\app.py", line 1508, in finalize_request
  File "C:\Users\Administrator\AppData\Roaming\Python\Python313\site-packages\flask\app.py", line 2002, in process_response
  File "C:\Users\Administrator\Desktop\company_finance_tracker\app.py", line 64, in add_security_headers
    for key, values in csp.items()
                       ^^^^^^^^^
AttributeError: 'str' object has no attribute 'items'

During handling of the above exception, another exception occurred:

Traceback (most recent call last):
  File "C:\Users\Administrator\AppData\Roaming\Python\Python313\site-packages\flask\app.py", line 1508, in finalize_request
  File "C:\Users\Administrator\AppData\Roaming\Python\Python313\site-packages\flask\app.py", line 2002, in process_response
  File "C:\Users\Administrator\Desktop\company_finance_tracker\app.py", line 64, in add_security_headers
    for key, values in csp.items()
                       ^^^^^^^^^
AttributeError: 'str' object has no attribute 'items'
2025-03-15 22:55:21,178 - app - [ERROR] - 10288 - 8288 - Exception on / [GET]
Traceback (most recent call last):
  File "C:\Users\Administrator\AppData\Roaming\Python\Python313\site-packages\flask\app.py", line 2190, in wsgi_app
    response = self.full_dispatch_request()
  File "C:\Users\Administrator\AppData\Roaming\Python\Python313\site-packages\flask\app.py", line 1487, in full_dispatch_request
    return self.finalize_request(rv)
           ~~~~~~~~~~~~~~~~~~~~~^^^^
  File "C:\Users\Administrator\AppData\Roaming\Python\Python313\site-packages\flask\app.py", line 1508, in finalize_request
    response = self.process_response(response)
  File "C:\Users\Administrator\AppData\Roaming\Python\Python313\site-packages\flask\app.py", line 2002, in process_response
    response = self.ensure_sync(func)(response)
  File "C:\Users\Administrator\Desktop\company_finance_tracker\app.py", line 64, in add_security_headers
    for key, values in csp.items()
                       ^^^^^^^^^
AttributeError: 'str' object has no attribute 'items'
2025-03-15 22:55:21,189 - app - [ERROR] - 10288 - 8288 - Request finalizing failed with an error while handling an error
Traceback (most recent call last):
  File "C:\Users\Administrator\AppData\Roaming\Python\Python313\site-packages\flask\app.py", line 2190, in wsgi_app
    response = self.full_dispatch_request()
  File "C:\Users\Administrator\AppData\Roaming\Python\Python313\site-packages\flask\app.py", line 1487, in full_dispatch_request
    return self.finalize_request(rv)
           ~~~~~~~~~~~~~~~~~~~~~^^^^
  File "C:\Users\Administrator\AppData\Roaming\Python\Python313\site-packages\flask\app.py", line 1508, in finalize_request
    response = self.process_response(response)
  File "C:\Users\Administrator\AppData\Roaming\Python\Python313\site-packages\flask\app.py", line 2002, in process_response
    response = self.ensure_sync(func)(response)
  File "C:\Users\Administrator\Desktop\company_finance_tracker\app.py", line 64, in add_security_headers
    for key, values in csp.items()
                       ^^^^^^^^^
AttributeError: 'str' object has no attribute 'items'

During handling of the above exception, another exception occurred:

Traceback (most recent call last):
  File "C:\Users\Administrator\AppData\Roaming\Python\Python313\site-packages\flask\app.py", line 1508, in finalize_request
    response = self.process_response(response)
  File "C:\Users\Administrator\AppData\Roaming\Python\Python313\site-packages\flask\app.py", line 2002, in process_response
    response = self.ensure_sync(func)(response)
  File "C:\Users\Administrator\Desktop\company_finance_tracker\app.py", line 64, in add_security_headers
    for key, values in csp.items()
                       ^^^^^^^^^
AttributeError: 'str' object has no attribute 'items'
2025-03-15 22:55:21,310 - app - [ERROR] - 10288 - 10700 - Exception on /favicon.ico [GET]
Traceback (most recent call last):
  File "C:\Users\Administrator\AppData\Roaming\Python\Python313\site-packages\flask\app.py", line 2190, in wsgi_app
    response = self.full_dispatch_request()
  File "C:\Users\Administrator\AppData\Roaming\Python\Python313\site-packages\flask\app.py", line 1487, in full_dispatch_request
    return self.finalize_request(rv)
           ~~~~~~~~~~~~~~~~~~~~~^^^^
  File "C:\Users\Administrator\AppData\Roaming\Python\Python313\site-packages\flask\app.py", line 1508, in finalize_request
    response = self.process_response(response)
  File "C:\Users\Administrator\AppData\Roaming\Python\Python313\site-packages\flask\app.py", line 2002, in process_response
    response = self.ensure_sync(func)(response)
  File "C:\Users\Administrator\Desktop\company_finance_tracker\app.py", line 64, in add_security_headers
    for key, values in csp.items()
                       ^^^^^^^^^
AttributeError: 'str' object has no attribute 'items'
2025-03-15 22:55:21,312 - app - [ERROR] - 10288 - 10700 - Request finalizing failed with an error while handling an error
Traceback (most recent call last):
  File "C:\Users\Administrator\AppData\Roaming\Python\Python313\site-packages\flask\app.py", line 2190, in wsgi_app
    response = self.full_dispatch_request()
  File "C:\Users\Administrator\AppData\Roaming\Python\Python313\site-packages\flask\app.py", line 1487, in full_dispatch_request
    return self.finalize_request(rv)
           ~~~~~~~~~~~~~~~~~~~~~^^^^
  File "C:\Users\Administrator\AppData\Roaming\Python\Python313\site-packages\flask\app.py", line 1508, in finalize_request
    response = self.process_response(response)
  File "C:\Users\Administrator\AppData\Roaming\Python\Python313\site-packages\flask\app.py", line 2002, in process_response
    response = self.ensure_sync(func)(response)
  File "C:\Users\Administrator\Desktop\company_finance_tracker\app.py", line 64, in add_security_headers
    for key, values in csp.items()
                       ^^^^^^^^^
AttributeError: 'str' object has no attribute 'items'

During handling of the above exception, another exception occurred:

Traceback (most recent call last):
  File "C:\Users\Administrator\AppData\Roaming\Python\Python313\site-packages\flask\app.py", line 1508, in finalize_request
    response = self.process_response(response)
  File "C:\Users\Administrator\AppData\Roaming\Python\Python313\site-packages\flask\app.py", line 2002, in process_response
    response = self.ensure_sync(func)(response)
  File "C:\Users\Administrator\Desktop\company_finance_tracker\app.py", line 64, in add_security_headers
    for key, values in csp.items()
                       ^^^^^^^^^
AttributeError: 'str' object has no attribute 'items'
2025-03-15 22:55:22,858 - app - [ERROR] - 10288 - 18444 - Exception on / [GET]
Traceback (most recent call last):
  File "C:\Users\Administrator\AppData\Roaming\Python\Python313\site-packages\flask\app.py", line 2190, in wsgi_app
    response = self.full_dispatch_request()
  File "C:\Users\Administrator\AppData\Roaming\Python\Python313\site-packages\flask\app.py", line 1487, in full_dispatch_request
    return self.finalize_request(rv)
           ~~~~~~~~~~~~~~~~~~~~~^^^^
  File "C:\Users\Administrator\AppData\Roaming\Python\Python313\site-packages\flask\app.py", line 1508, in finalize_request
    response = self.process_response(response)
  File "C:\Users\Administrator\AppData\Roaming\Python\Python313\site-packages\flask\app.py", line 2002, in process_response
    response = self.ensure_sync(func)(response)
  File "C:\Users\Administrator\Desktop\company_finance_tracker\app.py", line 64, in add_security_headers
    for key, values in csp.items()
                       ^^^^^^^^^
AttributeError: 'str' object has no attribute 'items'
2025-03-15 22:55:22,865 - app - [ERROR] - 10288 - 18444 - Request finalizing failed with an error while handling an error
Traceback (most recent call last):
  File "C:\Users\Administrator\AppData\Roaming\Python\Python313\site-packages\flask\app.py", line 2190, in wsgi_app
    response = self.full_dispatch_request()
  File "C:\Users\Administrator\AppData\Roaming\Python\Python313\site-packages\flask\app.py", line 1487, in full_dispatch_request
    return self.finalize_request(rv)
           ~~~~~~~~~~~~~~~~~~~~~^^^^
  File "C:\Users\Administrator\AppData\Roaming\Python\Python313\site-packages\flask\app.py", line 1508, in finalize_request
    response = self.process_response(response)
  File "C:\Users\Administrator\AppData\Roaming\Python\Python313\site-packages\flask\app.py", line 2002, in process_response
    response = self.ensure_sync(func)(response)
  File "C:\Users\Administrator\Desktop\company_finance_tracker\app.py", line 64, in add_security_headers
    for key, values in csp.items()
                       ^^^^^^^^^
AttributeError: 'str' object has no attribute 'items'

During handling of the above exception, another exception occurred:

Traceback (most recent call last):
  File "C:\Users\Administrator\AppData\Roaming\Python\Python313\site-packages\flask\app.py", line 1508, in finalize_request
    response = self.process_response(response)
  File "C:\Users\Administrator\AppData\Roaming\Python\Python313\site-packages\flask\app.py", line 2002, in process_response
    response = self.ensure_sync(func)(response)
  File "C:\Users\Administrator\Desktop\company_finance_tracker\app.py", line 64, in add_security_headers
    for key, values in csp.items()
                       ^^^^^^^^^
AttributeError: 'str' object has no attribute 'items'
2025-03-15 22:55:23,020 - app - [ERROR] - 10288 - 19416 - Exception on /favicon.ico [GET]
Traceback (most recent call last):
  File "C:\Users\Administrator\AppData\Roaming\Python\Python313\site-packages\flask\app.py", line 2190, in wsgi_app
    response = self.full_dispatch_request()
  File "C:\Users\Administrator\AppData\Roaming\Python\Python313\site-packages\flask\app.py", line 1487, in full_dispatch_request
    return self.finalize_request(rv)
           ~~~~~~~~~~~~~~~~~~~~~^^^^
  File "C:\Users\Administrator\AppData\Roaming\Python\Python313\site-packages\flask\app.py", line 1508, in finalize_request
    response = self.process_response(response)
  File "C:\Users\Administrator\AppData\Roaming\Python\Python313\site-packages\flask\app.py", line 2002, in process_response
    response = self.ensure_sync(func)(response)
  File "C:\Users\Administrator\Desktop\company_finance_tracker\app.py", line 64, in add_security_headers
    for key, values in csp.items()
                       ^^^^^^^^^
AttributeError: 'str' object has no attribute 'items'
2025-03-15 22:55:23,023 - app - [ERROR] - 10288 - 19416 - Request finalizing failed with an error while handling an error
Traceback (most recent call last):
  File "C:\Users\Administrator\AppData\Roaming\Python\Python313\site-packages\flask\app.py", line 2190, in wsgi_app
    response = self.full_dispatch_request()
  File "C:\Users\Administrator\AppData\Roaming\Python\Python313\site-packages\flask\app.py", line 1487, in full_dispatch_request
    return self.finalize_request(rv)
           ~~~~~~~~~~~~~~~~~~~~~^^^^
  File "C:\Users\Administrator\AppData\Roaming\Python\Python313\site-packages\flask\app.py", line 1508, in finalize_request
    response = self.process_response(response)
  File "C:\Users\Administrator\AppData\Roaming\Python\Python313\site-packages\flask\app.py", line 2002, in process_response
    response = self.ensure_sync(func)(response)
  File "C:\Users\Administrator\Desktop\company_finance_tracker\app.py", line 64, in add_security_headers
    for key, values in csp.items()
                       ^^^^^^^^^
AttributeError: 'str' object has no attribute 'items'

During handling of the above exception, another exception occurred:

Traceback (most recent call last):
  File "C:\Users\Administrator\AppData\Roaming\Python\Python313\site-packages\flask\app.py", line 1508, in finalize_request
    response = self.process_response(response)
  File "C:\Users\Administrator\AppData\Roaming\Python\Python313\site-packages\flask\app.py", line 2002, in process_response
    response = self.ensure_sync(func)(response)
  File "C:\Users\Administrator\Desktop\company_finance_tracker\app.py", line 64, in add_security_headers
    for key, values in csp.items()
                       ^^^^^^^^^
AttributeError: 'str' object has no attribute 'items'
2025-03-15 22:57:09,382 - app - [ERROR] - 10288 - 8288 - Exception on / [GET]
Traceback (most recent call last):
  File "C:\Users\Administrator\AppData\Roaming\Python\Python313\site-packages\flask\app.py", line 2190, in wsgi_app
    response = self.full_dispatch_request()
  File "C:\Users\Administrator\AppData\Roaming\Python\Python313\site-packages\flask\app.py", line 1487, in full_dispatch_request
    return self.finalize_request(rv)
           ~~~~~~~~~~~~~~~~~~~~~^^^^
  File "C:\Users\Administrator\AppData\Roaming\Python\Python313\site-packages\flask\app.py", line 1508, in finalize_request
    response = self.process_response(response)
  File "C:\Users\Administrator\AppData\Roaming\Python\Python313\site-packages\flask\app.py", line 2002, in process_response
    response = self.ensure_sync(func)(response)
  File "C:\Users\Administrator\Desktop\company_finance_tracker\app.py", line 64, in add_security_headers
AttributeError: 'str' object has no attribute 'items'
2025-03-15 22:57:09,385 - app - [ERROR] - 10288 - 8288 - Request finalizing failed with an error while handling an error
Traceback (most recent call last):
  File "C:\Users\Administrator\AppData\Roaming\Python\Python313\site-packages\flask\app.py", line 2190, in wsgi_app
    response = self.full_dispatch_request()
  File "C:\Users\Administrator\AppData\Roaming\Python\Python313\site-packages\flask\app.py", line 1487, in full_dispatch_request
    return self.finalize_request(rv)
           ~~~~~~~~~~~~~~~~~~~~~^^^^
  File "C:\Users\Administrator\AppData\Roaming\Python\Python313\site-packages\flask\app.py", line 1508, in finalize_request
    response = self.process_response(response)
  File "C:\Users\Administrator\AppData\Roaming\Python\Python313\site-packages\flask\app.py", line 2002, in process_response
    response = self.ensure_sync(func)(response)
  File "C:\Users\Administrator\Desktop\company_finance_tracker\app.py", line 64, in add_security_headers
AttributeError: 'str' object has no attribute 'items'

During handling of the above exception, another exception occurred:

Traceback (most recent call last):
  File "C:\Users\Administrator\AppData\Roaming\Python\Python313\site-packages\flask\app.py", line 1508, in finalize_request
    response = self.process_response(response)
  File "C:\Users\Administrator\AppData\Roaming\Python\Python313\site-packages\flask\app.py", line 2002, in process_response
    response = self.ensure_sync(func)(response)
  File "C:\Users\Administrator\Desktop\company_finance_tracker\app.py", line 64, in add_security_headers
AttributeError: 'str' object has no attribute 'items'
2025-03-15 22:57:09,436 - app - [ERROR] - 10288 - 10700 - Exception on /favicon.ico [GET]
Traceback (most recent call last):
  File "C:\Users\Administrator\AppData\Roaming\Python\Python313\site-packages\flask\app.py", line 2190, in wsgi_app
    response = self.full_dispatch_request()
  File "C:\Users\Administrator\AppData\Roaming\Python\Python313\site-packages\flask\app.py", line 1487, in full_dispatch_request
    return self.finalize_request(rv)
           ~~~~~~~~~~~~~~~~~~~~~^^^^
  File "C:\Users\Administrator\AppData\Roaming\Python\Python313\site-packages\flask\app.py", line 1508, in finalize_request
    response = self.process_response(response)
  File "C:\Users\Administrator\AppData\Roaming\Python\Python313\site-packages\flask\app.py", line 2002, in process_response
    response = self.ensure_sync(func)(response)
  File "C:\Users\Administrator\Desktop\company_finance_tracker\app.py", line 64, in add_security_headers
AttributeError: 'str' object has no attribute 'items'
2025-03-15 22:57:09,439 - app - [ERROR] - 10288 - 10700 - Request finalizing failed with an error while handling an error
Traceback (most recent call last):
  File "C:\Users\Administrator\AppData\Roaming\Python\Python313\site-packages\flask\app.py", line 2190, in wsgi_app
    response = self.full_dispatch_request()
  File "C:\Users\Administrator\AppData\Roaming\Python\Python313\site-packages\flask\app.py", line 1487, in full_dispatch_request
    return self.finalize_request(rv)
           ~~~~~~~~~~~~~~~~~~~~~^^^^
  File "C:\Users\Administrator\AppData\Roaming\Python\Python313\site-packages\flask\app.py", line 1508, in finalize_request
    response = self.process_response(response)
  File "C:\Users\Administrator\AppData\Roaming\Python\Python313\site-packages\flask\app.py", line 2002, in process_response
    response = self.ensure_sync(func)(response)
  File "C:\Users\Administrator\Desktop\company_finance_tracker\app.py", line 64, in add_security_headers
AttributeError: 'str' object has no attribute 'items'

During handling of the above exception, another exception occurred:

Traceback (most recent call last):
  File "C:\Users\Administrator\AppData\Roaming\Python\Python313\site-packages\flask\app.py", line 1508, in finalize_request
    response = self.process_response(response)
  File "C:\Users\Administrator\AppData\Roaming\Python\Python313\site-packages\flask\app.py", line 2002, in process_response
    response = self.ensure_sync(func)(response)
  File "C:\Users\Administrator\Desktop\company_finance_tracker\app.py", line 64, in add_security_headers
AttributeError: 'str' object has no attribute 'items'
2025-03-15 22:57:10,443 - app - [ERROR] - 10288 - 18444 - Exception on / [GET]
Traceback (most recent call last):
  File "C:\Users\Administrator\AppData\Roaming\Python\Python313\site-packages\flask\app.py", line 2190, in wsgi_app
    response = self.full_dispatch_request()
  File "C:\Users\Administrator\AppData\Roaming\Python\Python313\site-packages\flask\app.py", line 1487, in full_dispatch_request
    return self.finalize_request(rv)
           ~~~~~~~~~~~~~~~~~~~~~^^^^
  File "C:\Users\Administrator\AppData\Roaming\Python\Python313\site-packages\flask\app.py", line 1508, in finalize_request
    response = self.process_response(response)
  File "C:\Users\Administrator\AppData\Roaming\Python\Python313\site-packages\flask\app.py", line 2002, in process_response
    response = self.ensure_sync(func)(response)
  File "C:\Users\Administrator\Desktop\company_finance_tracker\app.py", line 64, in add_security_headers
AttributeError: 'str' object has no attribute 'items'
2025-03-15 22:57:10,447 - app - [ERROR] - 10288 - 18444 - Request finalizing failed with an error while handling an error
Traceback (most recent call last):
  File "C:\Users\Administrator\AppData\Roaming\Python\Python313\site-packages\flask\app.py", line 2190, in wsgi_app
    response = self.full_dispatch_request()
  File "C:\Users\Administrator\AppData\Roaming\Python\Python313\site-packages\flask\app.py", line 1487, in full_dispatch_request
    return self.finalize_request(rv)
           ~~~~~~~~~~~~~~~~~~~~~^^^^
  File "C:\Users\Administrator\AppData\Roaming\Python\Python313\site-packages\flask\app.py", line 1508, in finalize_request
    response = self.process_response(response)
  File "C:\Users\Administrator\AppData\Roaming\Python\Python313\site-packages\flask\app.py", line 2002, in process_response
    response = self.ensure_sync(func)(response)
  File "C:\Users\Administrator\Desktop\company_finance_tracker\app.py", line 64, in add_security_headers
AttributeError: 'str' object has no attribute 'items'

During handling of the above exception, another exception occurred:

Traceback (most recent call last):
  File "C:\Users\Administrator\AppData\Roaming\Python\Python313\site-packages\flask\app.py", line 1508, in finalize_request
    response = self.process_response(response)
  File "C:\Users\Administrator\AppData\Roaming\Python\Python313\site-packages\flask\app.py", line 2002, in process_response
    response = self.ensure_sync(func)(response)
  File "C:\Users\Administrator\Desktop\company_finance_tracker\app.py", line 64, in add_security_headers
AttributeError: 'str' object has no attribute 'items'
2025-03-15 22:57:10,501 - app - [ERROR] - 10288 - 19416 - Exception on /favicon.ico [GET]
Traceback (most recent call last):
  File "C:\Users\Administrator\AppData\Roaming\Python\Python313\site-packages\flask\app.py", line 2190, in wsgi_app
    response = self.full_dispatch_request()
  File "C:\Users\Administrator\AppData\Roaming\Python\Python313\site-packages\flask\app.py", line 1487, in full_dispatch_request
    return self.finalize_request(rv)
           ~~~~~~~~~~~~~~~~~~~~~^^^^
  File "C:\Users\Administrator\AppData\Roaming\Python\Python313\site-packages\flask\app.py", line 1508, in finalize_request
    response = self.process_response(response)
  File "C:\Users\Administrator\AppData\Roaming\Python\Python313\site-packages\flask\app.py", line 2002, in process_response
    response = self.ensure_sync(func)(response)
  File "C:\Users\Administrator\Desktop\company_finance_tracker\app.py", line 64, in add_security_headers
AttributeError: 'str' object has no attribute 'items'
2025-03-15 22:57:10,503 - app - [ERROR] - 10288 - 19416 - Request finalizing failed with an error while handling an error
Traceback (most recent call last):
  File "C:\Users\Administrator\AppData\Roaming\Python\Python313\site-packages\flask\app.py", line 2190, in wsgi_app
    response = self.full_dispatch_request()
  File "C:\Users\Administrator\AppData\Roaming\Python\Python313\site-packages\flask\app.py", line 1487, in full_dispatch_request
    return self.finalize_request(rv)
           ~~~~~~~~~~~~~~~~~~~~~^^^^
  File "C:\Users\Administrator\AppData\Roaming\Python\Python313\site-packages\flask\app.py", line 1508, in finalize_request
    response = self.process_response(response)
  File "C:\Users\Administrator\AppData\Roaming\Python\Python313\site-packages\flask\app.py", line 2002, in process_response
    response = self.ensure_sync(func)(response)
  File "C:\Users\Administrator\Desktop\company_finance_tracker\app.py", line 64, in add_security_headers
AttributeError: 'str' object has no attribute 'items'

During handling of the above exception, another exception occurred:

Traceback (most recent call last):
  File "C:\Users\Administrator\AppData\Roaming\Python\Python313\site-packages\flask\app.py", line 1508, in finalize_request
    response = self.process_response(response)
  File "C:\Users\Administrator\AppData\Roaming\Python\Python313\site-packages\flask\app.py", line 2002, in process_response
    response = self.ensure_sync(func)(response)
  File "C:\Users\Administrator\Desktop\company_finance_tracker\app.py", line 64, in add_security_headers
AttributeError: 'str' object has no attribute 'items'
2025-03-15 22:59:47,020 - app - [ERROR] - 10288 - 8288 - Exception on / [GET]
Traceback (most recent call last):
  File "C:\Users\Administrator\AppData\Roaming\Python\Python313\site-packages\flask\app.py", line 2190, in wsgi_app
    response = self.full_dispatch_request()
  File "C:\Users\Administrator\AppData\Roaming\Python\Python313\site-packages\flask\app.py", line 1487, in full_dispatch_request
    return self.finalize_request(rv)
           ~~~~~~~~~~~~~~~~~~~~~^^^^
  File "C:\Users\Administrator\AppData\Roaming\Python\Python313\site-packages\flask\app.py", line 1508, in finalize_request
    response = self.process_response(response)
  File "C:\Users\Administrator\AppData\Roaming\Python\Python313\site-packages\flask\app.py", line 2002, in process_response
    response = self.ensure_sync(func)(response)
  File "C:\Users\Administrator\Desktop\company_finance_tracker\app.py", line 64, in add_security_headers
AttributeError: 'str' object has no attribute 'items'
2025-03-15 22:59:47,024 - app - [ERROR] - 10288 - 8288 - Request finalizing failed with an error while handling an error
Traceback (most recent call last):
  File "C:\Users\Administrator\AppData\Roaming\Python\Python313\site-packages\flask\app.py", line 2190, in wsgi_app
    response = self.full_dispatch_request()
  File "C:\Users\Administrator\AppData\Roaming\Python\Python313\site-packages\flask\app.py", line 1487, in full_dispatch_request
    return self.finalize_request(rv)
           ~~~~~~~~~~~~~~~~~~~~~^^^^
  File "C:\Users\Administrator\AppData\Roaming\Python\Python313\site-packages\flask\app.py", line 1508, in finalize_request
    response = self.process_response(response)
  File "C:\Users\Administrator\AppData\Roaming\Python\Python313\site-packages\flask\app.py", line 2002, in process_response
    response = self.ensure_sync(func)(response)
  File "C:\Users\Administrator\Desktop\company_finance_tracker\app.py", line 64, in add_security_headers
AttributeError: 'str' object has no attribute 'items'

During handling of the above exception, another exception occurred:

Traceback (most recent call last):
  File "C:\Users\Administrator\AppData\Roaming\Python\Python313\site-packages\flask\app.py", line 1508, in finalize_request
    response = self.process_response(response)
  File "C:\Users\Administrator\AppData\Roaming\Python\Python313\site-packages\flask\app.py", line 2002, in process_response
    response = self.ensure_sync(func)(response)
  File "C:\Users\Administrator\Desktop\company_finance_tracker\app.py", line 64, in add_security_headers
AttributeError: 'str' object has no attribute 'items'
2025-03-15 22:59:47,137 - app - [ERROR] - 10288 - 10700 - Exception on /favicon.ico [GET]
Traceback (most recent call last):
  File "C:\Users\Administrator\AppData\Roaming\Python\Python313\site-packages\flask\app.py", line 2190, in wsgi_app
    response = self.full_dispatch_request()
  File "C:\Users\Administrator\AppData\Roaming\Python\Python313\site-packages\flask\app.py", line 1487, in full_dispatch_request
    return self.finalize_request(rv)
           ~~~~~~~~~~~~~~~~~~~~~^^^^
  File "C:\Users\Administrator\AppData\Roaming\Python\Python313\site-packages\flask\app.py", line 1508, in finalize_request
    response = self.process_response(response)
  File "C:\Users\Administrator\AppData\Roaming\Python\Python313\site-packages\flask\app.py", line 2002, in process_response
    response = self.ensure_sync(func)(response)
  File "C:\Users\Administrator\Desktop\company_finance_tracker\app.py", line 64, in add_security_headers
AttributeError: 'str' object has no attribute 'items'
2025-03-15 22:59:47,141 - app - [ERROR] - 10288 - 10700 - Request finalizing failed with an error while handling an error
Traceback (most recent call last):
  File "C:\Users\Administrator\AppData\Roaming\Python\Python313\site-packages\flask\app.py", line 2190, in wsgi_app
    response = self.full_dispatch_request()
  File "C:\Users\Administrator\AppData\Roaming\Python\Python313\site-packages\flask\app.py", line 1487, in full_dispatch_request
    return self.finalize_request(rv)
           ~~~~~~~~~~~~~~~~~~~~~^^^^
  File "C:\Users\Administrator\AppData\Roaming\Python\Python313\site-packages\flask\app.py", line 1508, in finalize_request
    response = self.process_response(response)
  File "C:\Users\Administrator\AppData\Roaming\Python\Python313\site-packages\flask\app.py", line 2002, in process_response
    response = self.ensure_sync(func)(response)
  File "C:\Users\Administrator\Desktop\company_finance_tracker\app.py", line 64, in add_security_headers
AttributeError: 'str' object has no attribute 'items'

During handling of the above exception, another exception occurred:

Traceback (most recent call last):
  File "C:\Users\Administrator\AppData\Roaming\Python\Python313\site-packages\flask\app.py", line 1508, in finalize_request
    response = self.process_response(response)
  File "C:\Users\Administrator\AppData\Roaming\Python\Python313\site-packages\flask\app.py", line 2002, in process_response
    response = self.ensure_sync(func)(response)
  File "C:\Users\Administrator\Desktop\company_finance_tracker\app.py", line 64, in add_security_headers
AttributeError: 'str' object has no attribute 'items'
2025-03-15 23:01:48,871 - app - [ERROR] - 10288 - 18444 - Exception on / [GET]
Traceback (most recent call last):
  File "C:\Users\Administrator\AppData\Roaming\Python\Python313\site-packages\flask\app.py", line 2190, in wsgi_app
    response = self.full_dispatch_request()
  File "C:\Users\Administrator\AppData\Roaming\Python\Python313\site-packages\flask\app.py", line 1487, in full_dispatch_request
    return self.finalize_request(rv)
           ~~~~~~~~~~~~~~~~~~~~~^^^^
  File "C:\Users\Administrator\AppData\Roaming\Python\Python313\site-packages\flask\app.py", line 1508, in finalize_request
    response = self.process_response(response)
  File "C:\Users\Administrator\AppData\Roaming\Python\Python313\site-packages\flask\app.py", line 2002, in process_response
    response = self.ensure_sync(func)(response)
  File "C:\Users\Administrator\Desktop\company_finance_tracker\app.py", line 64, in add_security_headers
AttributeError: 'str' object has no attribute 'items'
2025-03-15 23:01:48,876 - app - [ERROR] - 10288 - 18444 - Request finalizing failed with an error while handling an error
Traceback (most recent call last):
  File "C:\Users\Administrator\AppData\Roaming\Python\Python313\site-packages\flask\app.py", line 2190, in wsgi_app
    response = self.full_dispatch_request()
  File "C:\Users\Administrator\AppData\Roaming\Python\Python313\site-packages\flask\app.py", line 1487, in full_dispatch_request
    return self.finalize_request(rv)
           ~~~~~~~~~~~~~~~~~~~~~^^^^
  File "C:\Users\Administrator\AppData\Roaming\Python\Python313\site-packages\flask\app.py", line 1508, in finalize_request
    response = self.process_response(response)
  File "C:\Users\Administrator\AppData\Roaming\Python\Python313\site-packages\flask\app.py", line 2002, in process_response
    response = self.ensure_sync(func)(response)
  File "C:\Users\Administrator\Desktop\company_finance_tracker\app.py", line 64, in add_security_headers
AttributeError: 'str' object has no attribute 'items'

During handling of the above exception, another exception occurred:

Traceback (most recent call last):
  File "C:\Users\Administrator\AppData\Roaming\Python\Python313\site-packages\flask\app.py", line 1508, in finalize_request
    response = self.process_response(response)
  File "C:\Users\Administrator\AppData\Roaming\Python\Python313\site-packages\flask\app.py", line 2002, in process_response
    response = self.ensure_sync(func)(response)
  File "C:\Users\Administrator\Desktop\company_finance_tracker\app.py", line 64, in add_security_headers
AttributeError: 'str' object has no attribute 'items'
2025-03-15 23:01:48,980 - app - [ERROR] - 10288 - 19416 - Exception on /favicon.ico [GET]
Traceback (most recent call last):
  File "C:\Users\Administrator\AppData\Roaming\Python\Python313\site-packages\flask\app.py", line 2190, in wsgi_app
    response = self.full_dispatch_request()
  File "C:\Users\Administrator\AppData\Roaming\Python\Python313\site-packages\flask\app.py", line 1487, in full_dispatch_request
    return self.finalize_request(rv)
           ~~~~~~~~~~~~~~~~~~~~~^^^^
  File "C:\Users\Administrator\AppData\Roaming\Python\Python313\site-packages\flask\app.py", line 1508, in finalize_request
    response = self.process_response(response)
  File "C:\Users\Administrator\AppData\Roaming\Python\Python313\site-packages\flask\app.py", line 2002, in process_response
    response = self.ensure_sync(func)(response)
  File "C:\Users\Administrator\Desktop\company_finance_tracker\app.py", line 64, in add_security_headers
AttributeError: 'str' object has no attribute 'items'
2025-03-15 23:01:48,983 - app - [ERROR] - 10288 - 19416 - Request finalizing failed with an error while handling an error
Traceback (most recent call last):
  File "C:\Users\Administrator\AppData\Roaming\Python\Python313\site-packages\flask\app.py", line 2190, in wsgi_app
    response = self.full_dispatch_request()
  File "C:\Users\Administrator\AppData\Roaming\Python\Python313\site-packages\flask\app.py", line 1487, in full_dispatch_request
    return self.finalize_request(rv)
           ~~~~~~~~~~~~~~~~~~~~~^^^^
  File "C:\Users\Administrator\AppData\Roaming\Python\Python313\site-packages\flask\app.py", line 1508, in finalize_request
    response = self.process_response(response)
  File "C:\Users\Administrator\AppData\Roaming\Python\Python313\site-packages\flask\app.py", line 2002, in process_response
    response = self.ensure_sync(func)(response)
  File "C:\Users\Administrator\Desktop\company_finance_tracker\app.py", line 64, in add_security_headers
AttributeError: 'str' object has no attribute 'items'

During handling of the above exception, another exception occurred:

Traceback (most recent call last):
  File "C:\Users\Administrator\AppData\Roaming\Python\Python313\site-packages\flask\app.py", line 1508, in finalize_request
    response = self.process_response(response)
  File "C:\Users\Administrator\AppData\Roaming\Python\Python313\site-packages\flask\app.py", line 2002, in process_response
    response = self.ensure_sync(func)(response)
  File "C:\Users\Administrator\Desktop\company_finance_tracker\app.py", line 64, in add_security_headers
AttributeError: 'str' object has no attribute 'items'
2025-03-15 23:09:39,739 - app - [ERROR] - 10288 - 8288 - Exception on / [GET]
Traceback (most recent call last):
  File "C:\Users\Administrator\AppData\Roaming\Python\Python313\site-packages\flask\app.py", line 2190, in wsgi_app
    response = self.full_dispatch_request()
  File "C:\Users\Administrator\AppData\Roaming\Python\Python313\site-packages\flask\app.py", line 1487, in full_dispatch_request
    return self.finalize_request(rv)
           ~~~~~~~~~~~~~~~~~~~~~^^^^
  File "C:\Users\Administrator\AppData\Roaming\Python\Python313\site-packages\flask\app.py", line 1508, in finalize_request
    response = self.process_response(response)
  File "C:\Users\Administrator\AppData\Roaming\Python\Python313\site-packages\flask\app.py", line 2002, in process_response
    response = self.ensure_sync(func)(response)
  File "C:\Users\Administrator\Desktop\company_finance_tracker\app.py", line 64, in add_security_headers
AttributeError: 'str' object has no attribute 'items'
2025-03-15 23:09:39,743 - app - [ERROR] - 10288 - 8288 - Request finalizing failed with an error while handling an error
Traceback (most recent call last):
  File "C:\Users\Administrator\AppData\Roaming\Python\Python313\site-packages\flask\app.py", line 2190, in wsgi_app
    response = self.full_dispatch_request()
  File "C:\Users\Administrator\AppData\Roaming\Python\Python313\site-packages\flask\app.py", line 1487, in full_dispatch_request
    return self.finalize_request(rv)
           ~~~~~~~~~~~~~~~~~~~~~^^^^
  File "C:\Users\Administrator\AppData\Roaming\Python\Python313\site-packages\flask\app.py", line 1508, in finalize_request
    response = self.process_response(response)
  File "C:\Users\Administrator\AppData\Roaming\Python\Python313\site-packages\flask\app.py", line 2002, in process_response
    response = self.ensure_sync(func)(response)
  File "C:\Users\Administrator\Desktop\company_finance_tracker\app.py", line 64, in add_security_headers
AttributeError: 'str' object has no attribute 'items'

During handling of the above exception, another exception occurred:

Traceback (most recent call last):
  File "C:\Users\Administrator\AppData\Roaming\Python\Python313\site-packages\flask\app.py", line 1508, in finalize_request
    response = self.process_response(response)
  File "C:\Users\Administrator\AppData\Roaming\Python\Python313\site-packages\flask\app.py", line 2002, in process_response
    response = self.ensure_sync(func)(response)
  File "C:\Users\Administrator\Desktop\company_finance_tracker\app.py", line 64, in add_security_headers
AttributeError: 'str' object has no attribute 'items'
2025-03-15 23:09:39,797 - app - [ERROR] - 10288 - 10700 - Exception on /favicon.ico [GET]
Traceback (most recent call last):
  File "C:\Users\Administrator\AppData\Roaming\Python\Python313\site-packages\flask\app.py", line 2190, in wsgi_app
    response = self.full_dispatch_request()
  File "C:\Users\Administrator\AppData\Roaming\Python\Python313\site-packages\flask\app.py", line 1487, in full_dispatch_request
    return self.finalize_request(rv)
           ~~~~~~~~~~~~~~~~~~~~~^^^^
  File "C:\Users\Administrator\AppData\Roaming\Python\Python313\site-packages\flask\app.py", line 1508, in finalize_request
    response = self.process_response(response)
  File "C:\Users\Administrator\AppData\Roaming\Python\Python313\site-packages\flask\app.py", line 2002, in process_response
    response = self.ensure_sync(func)(response)
  File "C:\Users\Administrator\Desktop\company_finance_tracker\app.py", line 64, in add_security_headers
AttributeError: 'str' object has no attribute 'items'
2025-03-15 23:09:39,799 - app - [ERROR] - 10288 - 10700 - Request finalizing failed with an error while handling an error
Traceback (most recent call last):
  File "C:\Users\Administrator\AppData\Roaming\Python\Python313\site-packages\flask\app.py", line 2190, in wsgi_app
    response = self.full_dispatch_request()
  File "C:\Users\Administrator\AppData\Roaming\Python\Python313\site-packages\flask\app.py", line 1487, in full_dispatch_request
    return self.finalize_request(rv)
           ~~~~~~~~~~~~~~~~~~~~~^^^^
  File "C:\Users\Administrator\AppData\Roaming\Python\Python313\site-packages\flask\app.py", line 1508, in finalize_request
    response = self.process_response(response)
  File "C:\Users\Administrator\AppData\Roaming\Python\Python313\site-packages\flask\app.py", line 2002, in process_response
    response = self.ensure_sync(func)(response)
  File "C:\Users\Administrator\Desktop\company_finance_tracker\app.py", line 64, in add_security_headers
AttributeError: 'str' object has no attribute 'items'

During handling of the above exception, another exception occurred:

Traceback (most recent call last):
  File "C:\Users\Administrator\AppData\Roaming\Python\Python313\site-packages\flask\app.py", line 1508, in finalize_request
    response = self.process_response(response)
  File "C:\Users\Administrator\AppData\Roaming\Python\Python313\site-packages\flask\app.py", line 2002, in process_response
    response = self.ensure_sync(func)(response)
  File "C:\Users\Administrator\Desktop\company_finance_tracker\app.py", line 64, in add_security_headers
AttributeError: 'str' object has no attribute 'items'
2025-03-15 23:09:40,626 - app - [ERROR] - 10288 - 18444 - Exception on / [GET]
Traceback (most recent call last):
  File "C:\Users\Administrator\AppData\Roaming\Python\Python313\site-packages\flask\app.py", line 2190, in wsgi_app
    response = self.full_dispatch_request()
  File "C:\Users\Administrator\AppData\Roaming\Python\Python313\site-packages\flask\app.py", line 1487, in full_dispatch_request
    return self.finalize_request(rv)
           ~~~~~~~~~~~~~~~~~~~~~^^^^
  File "C:\Users\Administrator\AppData\Roaming\Python\Python313\site-packages\flask\app.py", line 1508, in finalize_request
    response = self.process_response(response)
  File "C:\Users\Administrator\AppData\Roaming\Python\Python313\site-packages\flask\app.py", line 2002, in process_response
    response = self.ensure_sync(func)(response)
  File "C:\Users\Administrator\Desktop\company_finance_tracker\app.py", line 64, in add_security_headers
AttributeError: 'str' object has no attribute 'items'
2025-03-15 23:09:40,628 - app - [ERROR] - 10288 - 18444 - Request finalizing failed with an error while handling an error
Traceback (most recent call last):
  File "C:\Users\Administrator\AppData\Roaming\Python\Python313\site-packages\flask\app.py", line 2190, in wsgi_app
    response = self.full_dispatch_request()
  File "C:\Users\Administrator\AppData\Roaming\Python\Python313\site-packages\flask\app.py", line 1487, in full_dispatch_request
    return self.finalize_request(rv)
           ~~~~~~~~~~~~~~~~~~~~~^^^^
  File "C:\Users\Administrator\AppData\Roaming\Python\Python313\site-packages\flask\app.py", line 1508, in finalize_request
    response = self.process_response(response)
  File "C:\Users\Administrator\AppData\Roaming\Python\Python313\site-packages\flask\app.py", line 2002, in process_response
    response = self.ensure_sync(func)(response)
  File "C:\Users\Administrator\Desktop\company_finance_tracker\app.py", line 64, in add_security_headers
AttributeError: 'str' object has no attribute 'items'

During handling of the above exception, another exception occurred:

Traceback (most recent call last):
  File "C:\Users\Administrator\AppData\Roaming\Python\Python313\site-packages\flask\app.py", line 1508, in finalize_request
    response = self.process_response(response)
  File "C:\Users\Administrator\AppData\Roaming\Python\Python313\site-packages\flask\app.py", line 2002, in process_response
    response = self.ensure_sync(func)(response)
  File "C:\Users\Administrator\Desktop\company_finance_tracker\app.py", line 64, in add_security_headers
AttributeError: 'str' object has no attribute 'items'
2025-03-15 23:09:40,682 - app - [ERROR] - 10288 - 19416 - Exception on /favicon.ico [GET]
Traceback (most recent call last):
  File "C:\Users\Administrator\AppData\Roaming\Python\Python313\site-packages\flask\app.py", line 2190, in wsgi_app
    response = self.full_dispatch_request()
  File "C:\Users\Administrator\AppData\Roaming\Python\Python313\site-packages\flask\app.py", line 1487, in full_dispatch_request
    return self.finalize_request(rv)
           ~~~~~~~~~~~~~~~~~~~~~^^^^
  File "C:\Users\Administrator\AppData\Roaming\Python\Python313\site-packages\flask\app.py", line 1508, in finalize_request
    response = self.process_response(response)
  File "C:\Users\Administrator\AppData\Roaming\Python\Python313\site-packages\flask\app.py", line 2002, in process_response
    response = self.ensure_sync(func)(response)
  File "C:\Users\Administrator\Desktop\company_finance_tracker\app.py", line 64, in add_security_headers
AttributeError: 'str' object has no attribute 'items'
2025-03-15 23:09:40,684 - app - [ERROR] - 10288 - 19416 - Request finalizing failed with an error while handling an error
Traceback (most recent call last):
  File "C:\Users\Administrator\AppData\Roaming\Python\Python313\site-packages\flask\app.py", line 2190, in wsgi_app
    response = self.full_dispatch_request()
  File "C:\Users\Administrator\AppData\Roaming\Python\Python313\site-packages\flask\app.py", line 1487, in full_dispatch_request
    return self.finalize_request(rv)
           ~~~~~~~~~~~~~~~~~~~~~^^^^
  File "C:\Users\Administrator\AppData\Roaming\Python\Python313\site-packages\flask\app.py", line 1508, in finalize_request
    response = self.process_response(response)
  File "C:\Users\Administrator\AppData\Roaming\Python\Python313\site-packages\flask\app.py", line 2002, in process_response
    response = self.ensure_sync(func)(response)
  File "C:\Users\Administrator\Desktop\company_finance_tracker\app.py", line 64, in add_security_headers
AttributeError: 'str' object has no attribute 'items'

During handling of the above exception, another exception occurred:

Traceback (most recent call last):
  File "C:\Users\Administrator\AppData\Roaming\Python\Python313\site-packages\flask\app.py", line 1508, in finalize_request
    response = self.process_response(response)
  File "C:\Users\Administrator\AppData\Roaming\Python\Python313\site-packages\flask\app.py", line 2002, in process_response
    response = self.ensure_sync(func)(response)
  File "C:\Users\Administrator\Desktop\company_finance_tracker\app.py", line 64, in add_security_headers
AttributeError: 'str' object has no attribute 'items'
2025-03-15 23:09:41,001 - app - [ERROR] - 10288 - 8288 - Exception on / [GET]
Traceback (most recent call last):
  File "C:\Users\Administrator\AppData\Roaming\Python\Python313\site-packages\flask\app.py", line 2190, in wsgi_app
    response = self.full_dispatch_request()
  File "C:\Users\Administrator\AppData\Roaming\Python\Python313\site-packages\flask\app.py", line 1487, in full_dispatch_request
    return self.finalize_request(rv)
           ~~~~~~~~~~~~~~~~~~~~~^^^^
  File "C:\Users\Administrator\AppData\Roaming\Python\Python313\site-packages\flask\app.py", line 1508, in finalize_request
    response = self.process_response(response)
  File "C:\Users\Administrator\AppData\Roaming\Python\Python313\site-packages\flask\app.py", line 2002, in process_response
    response = self.ensure_sync(func)(response)
  File "C:\Users\Administrator\Desktop\company_finance_tracker\app.py", line 64, in add_security_headers
AttributeError: 'str' object has no attribute 'items'
2025-03-15 23:09:41,004 - app - [ERROR] - 10288 - 8288 - Request finalizing failed with an error while handling an error
Traceback (most recent call last):
  File "C:\Users\Administrator\AppData\Roaming\Python\Python313\site-packages\flask\app.py", line 2190, in wsgi_app
    response = self.full_dispatch_request()
  File "C:\Users\Administrator\AppData\Roaming\Python\Python313\site-packages\flask\app.py", line 1487, in full_dispatch_request
    return self.finalize_request(rv)
           ~~~~~~~~~~~~~~~~~~~~~^^^^
  File "C:\Users\Administrator\AppData\Roaming\Python\Python313\site-packages\flask\app.py", line 1508, in finalize_request
    response = self.process_response(response)
  File "C:\Users\Administrator\AppData\Roaming\Python\Python313\site-packages\flask\app.py", line 2002, in process_response
    response = self.ensure_sync(func)(response)
  File "C:\Users\Administrator\Desktop\company_finance_tracker\app.py", line 64, in add_security_headers
AttributeError: 'str' object has no attribute 'items'

During handling of the above exception, another exception occurred:

Traceback (most recent call last):
  File "C:\Users\Administrator\AppData\Roaming\Python\Python313\site-packages\flask\app.py", line 1508, in finalize_request
    response = self.process_response(response)
  File "C:\Users\Administrator\AppData\Roaming\Python\Python313\site-packages\flask\app.py", line 2002, in process_response
    response = self.ensure_sync(func)(response)
  File "C:\Users\Administrator\Desktop\company_finance_tracker\app.py", line 64, in add_security_headers
AttributeError: 'str' object has no attribute 'items'
2025-03-15 23:09:41,096 - app - [ERROR] - 10288 - 10700 - Exception on /favicon.ico [GET]
Traceback (most recent call last):
  File "C:\Users\Administrator\AppData\Roaming\Python\Python313\site-packages\flask\app.py", line 2190, in wsgi_app
    response = self.full_dispatch_request()
  File "C:\Users\Administrator\AppData\Roaming\Python\Python313\site-packages\flask\app.py", line 1487, in full_dispatch_request
    return self.finalize_request(rv)
           ~~~~~~~~~~~~~~~~~~~~~^^^^
  File "C:\Users\Administrator\AppData\Roaming\Python\Python313\site-packages\flask\app.py", line 1508, in finalize_request
    response = self.process_response(response)
  File "C:\Users\Administrator\AppData\Roaming\Python\Python313\site-packages\flask\app.py", line 2002, in process_response
    response = self.ensure_sync(func)(response)
  File "C:\Users\Administrator\Desktop\company_finance_tracker\app.py", line 64, in add_security_headers
AttributeError: 'str' object has no attribute 'items'
2025-03-15 23:09:41,098 - app - [ERROR] - 10288 - 10700 - Request finalizing failed with an error while handling an error
Traceback (most recent call last):
  File "C:\Users\Administrator\AppData\Roaming\Python\Python313\site-packages\flask\app.py", line 2190, in wsgi_app
    response = self.full_dispatch_request()
  File "C:\Users\Administrator\AppData\Roaming\Python\Python313\site-packages\flask\app.py", line 1487, in full_dispatch_request
    return self.finalize_request(rv)
           ~~~~~~~~~~~~~~~~~~~~~^^^^
  File "C:\Users\Administrator\AppData\Roaming\Python\Python313\site-packages\flask\app.py", line 1508, in finalize_request
    response = self.process_response(response)
  File "C:\Users\Administrator\AppData\Roaming\Python\Python313\site-packages\flask\app.py", line 2002, in process_response
    response = self.ensure_sync(func)(response)
  File "C:\Users\Administrator\Desktop\company_finance_tracker\app.py", line 64, in add_security_headers
AttributeError: 'str' object has no attribute 'items'

During handling of the above exception, another exception occurred:

Traceback (most recent call last):
  File "C:\Users\Administrator\AppData\Roaming\Python\Python313\site-packages\flask\app.py", line 1508, in finalize_request
    response = self.process_response(response)
  File "C:\Users\Administrator\AppData\Roaming\Python\Python313\site-packages\flask\app.py", line 2002, in process_response
    response = self.ensure_sync(func)(response)
  File "C:\Users\Administrator\Desktop\company_finance_tracker\app.py", line 64, in add_security_headers
AttributeError: 'str' object has no attribute 'items'
2025-03-15 23:09:41,217 - app - [ERROR] - 10288 - 18444 - Exception on / [GET]
Traceback (most recent call last):
  File "C:\Users\Administrator\AppData\Roaming\Python\Python313\site-packages\flask\app.py", line 2190, in wsgi_app
    response = self.full_dispatch_request()
  File "C:\Users\Administrator\AppData\Roaming\Python\Python313\site-packages\flask\app.py", line 1487, in full_dispatch_request
    return self.finalize_request(rv)
           ~~~~~~~~~~~~~~~~~~~~~^^^^
  File "C:\Users\Administrator\AppData\Roaming\Python\Python313\site-packages\flask\app.py", line 1508, in finalize_request
    response = self.process_response(response)
  File "C:\Users\Administrator\AppData\Roaming\Python\Python313\site-packages\flask\app.py", line 2002, in process_response
    response = self.ensure_sync(func)(response)
  File "C:\Users\Administrator\Desktop\company_finance_tracker\app.py", line 64, in add_security_headers
AttributeError: 'str' object has no attribute 'items'
2025-03-15 23:09:41,218 - app - [ERROR] - 10288 - 18444 - Request finalizing failed with an error while handling an error
Traceback (most recent call last):
  File "C:\Users\Administrator\AppData\Roaming\Python\Python313\site-packages\flask\app.py", line 2190, in wsgi_app
    response = self.full_dispatch_request()
  File "C:\Users\Administrator\AppData\Roaming\Python\Python313\site-packages\flask\app.py", line 1487, in full_dispatch_request
    return self.finalize_request(rv)
           ~~~~~~~~~~~~~~~~~~~~~^^^^
  File "C:\Users\Administrator\AppData\Roaming\Python\Python313\site-packages\flask\app.py", line 1508, in finalize_request
    response = self.process_response(response)
  File "C:\Users\Administrator\AppData\Roaming\Python\Python313\site-packages\flask\app.py", line 2002, in process_response
    response = self.ensure_sync(func)(response)
  File "C:\Users\Administrator\Desktop\company_finance_tracker\app.py", line 64, in add_security_headers
AttributeError: 'str' object has no attribute 'items'

During handling of the above exception, another exception occurred:

Traceback (most recent call last):
  File "C:\Users\Administrator\AppData\Roaming\Python\Python313\site-packages\flask\app.py", line 1508, in finalize_request
    response = self.process_response(response)
  File "C:\Users\Administrator\AppData\Roaming\Python\Python313\site-packages\flask\app.py", line 2002, in process_response
    response = self.ensure_sync(func)(response)
  File "C:\Users\Administrator\Desktop\company_finance_tracker\app.py", line 64, in add_security_headers
AttributeError: 'str' object has no attribute 'items'
2025-03-15 23:09:41,269 - app - [ERROR] - 10288 - 19416 - Exception on /favicon.ico [GET]
Traceback (most recent call last):
  File "C:\Users\Administrator\AppData\Roaming\Python\Python313\site-packages\flask\app.py", line 2190, in wsgi_app
    response = self.full_dispatch_request()
  File "C:\Users\Administrator\AppData\Roaming\Python\Python313\site-packages\flask\app.py", line 1487, in full_dispatch_request
    return self.finalize_request(rv)
           ~~~~~~~~~~~~~~~~~~~~~^^^^
  File "C:\Users\Administrator\AppData\Roaming\Python\Python313\site-packages\flask\app.py", line 1508, in finalize_request
    response = self.process_response(response)
  File "C:\Users\Administrator\AppData\Roaming\Python\Python313\site-packages\flask\app.py", line 2002, in process_response
    response = self.ensure_sync(func)(response)
  File "C:\Users\Administrator\Desktop\company_finance_tracker\app.py", line 64, in add_security_headers
AttributeError: 'str' object has no attribute 'items'
2025-03-15 23:09:41,270 - app - [ERROR] - 10288 - 19416 - Request finalizing failed with an error while handling an error
Traceback (most recent call last):
  File "C:\Users\Administrator\AppData\Roaming\Python\Python313\site-packages\flask\app.py", line 2190, in wsgi_app
    response = self.full_dispatch_request()
  File "C:\Users\Administrator\AppData\Roaming\Python\Python313\site-packages\flask\app.py", line 1487, in full_dispatch_request
    return self.finalize_request(rv)
           ~~~~~~~~~~~~~~~~~~~~~^^^^
  File "C:\Users\Administrator\AppData\Roaming\Python\Python313\site-packages\flask\app.py", line 1508, in finalize_request
    response = self.process_response(response)
  File "C:\Users\Administrator\AppData\Roaming\Python\Python313\site-packages\flask\app.py", line 2002, in process_response
    response = self.ensure_sync(func)(response)
  File "C:\Users\Administrator\Desktop\company_finance_tracker\app.py", line 64, in add_security_headers
AttributeError: 'str' object has no attribute 'items'

During handling of the above exception, another exception occurred:

Traceback (most recent call last):
  File "C:\Users\Administrator\AppData\Roaming\Python\Python313\site-packages\flask\app.py", line 1508, in finalize_request
    response = self.process_response(response)
  File "C:\Users\Administrator\AppData\Roaming\Python\Python313\site-packages\flask\app.py", line 2002, in process_response
    response = self.ensure_sync(func)(response)
  File "C:\Users\Administrator\Desktop\company_finance_tracker\app.py", line 64, in add_security_headers
AttributeError: 'str' object has no attribute 'items'
